Workbook

Sheet per_seed
A1: arm | B1: bots | C1: seed | D1: Items | E1: Lines | F1: Orders | G1: Pile-on | H1: Trips | I1: Trips/Orders | J1: m/Line | K1: EOR(kJ/order) | L1: TurnoverMedian(s) | M1: StationIdle(%)
A2: m4g_6b | B2: 6 | C2: 0 | D2: 1426 | E2: 945 | F2: 616 | G2: 5.5 | H2: 112 | I2: 0.18181818 | J2: 9.8725978 | K2: 1.1974569 | L2: 803.95556 | M2: 1.0283951
A3: m4g_6b | B3: 6 | C3: 1 | D3: 1412 | E3: 925 | F3: 580 | G3: 5.1785714 | H3: 112 | I3: 0.19310345 | J3: 9.5592069 | K3: 1.2106212 | L3: 908.75556 | M3: 1.9962963
A4: m4g_6b | B4: 6 | C4: 2 | D4: 1425 | E4: 976 | F4: 613 | G4: 5.4247788 | H4: 113 | I4: 0.18433931 | J4: 9.0215084 | K4: 1.1686299 | L4: 809.86667 | M4: 1.1067901
A5: m4g_6b | B5: 6 | C5: 3 | D5: 1410 | E5: 940 | F5: 599 | G5: 5.5462963 | H5: 108 | I5: 0.1803005 | J5: 8.9386356 | K5: 1.1279479 | L5: 901.33333 | M5: 2.1598765
A6: m4g_6b | B6: 6 | C6: 4 | D6: 1417 | E6: 940 | F6: 583 | G6: 5.159292 | H6: 113 | I6: 0.19382504 | J6: 9.2539614 | K6: 1.2081299 | L6: 783.2 | M6: 1.662963
A7: m4g_6b | B7: 6 | C7: 5 | D7: 1418 | E7: 929 | F7: 587 | G7: 5.017094 | H7: 117 | I7: 0.19931857 | J7: 9.9289559 | K7: 1.2554114 | L7: 763.42222 | M7: 1.6024691
A8: m4g_6b | B8: 6 | C8: 6 | D8: 1429 | E8: 964 | F8: 603 | G8: 5.5321101 | H8: 109 | I8: 0.18076285 | J8: 9.0890776 | K8: 1.1630018 | L8: 844.75556 | M8: 0.8287037
A9: m4g_6b | B9: 6 | C9: 7 | D9: 1414 | E9: 937 | F9: 603 | G9: 5.3839286 | H9: 112 | I9: 0.18573798 | J9: 9.3416919 | K9: 1.1725442 | L9: 822.48889 | M9: 1.8222222
A10: m4g_6b | B10: 6 | C10: 8 | D10: 1420 | E10: 954 | F10: 603 | G10: 5.2894737 | H10: 114 | I10: 0.18905473 | J10: 9.4916143 | K10: 1.2122323 | L10: 797.6 | M10: 1.4277778
A11: m4g_6b | B11: 6 | C11: 9 | D11: 1428 | E11: 951 | F11: 604 | G11: 5.3451327 | H11: 113 | I11: 0.18708609 | J11: 9.2384902 | K11: 1.17927 | L11: 872.48889 | M11: 0.89506173
A12: m4g_legacy_6b | B12: 6 | C12: 0 | D12: 1388 | E12: 931 | F12: 612 | G12: 4.4671533 | H12: 137 | I12: 0.22385621 | J12: 11.51081 | K12: 1.3937758 | L12: 822.26667 | M12: 3.6493827
A13: m4g_legacy_6b | B13: 6 | C13: 1 | D13: 1410 | E13: 925 | F13: 574 | G13: 4.2835821 | H13: 134 | I13: 0.23344948 | J13: 11.322123 | K13: 1.4721013 | L13: 935.37778 | M13: 2.1558642
... A41: m4g_legacy_10b | B41: 10 | C41: 9 | D41: 1427 | E41: 956 | F41: 604 | G41: 2.9178744 | H41: 207 | I41: 0.34271523 | J41: 15.817992 | K41: 2.0274977 | L41: 752.22222 | M41: 1.0185185

Sheet excel_check
A1: kind | B1: arm_or_comparison | C1: metric | D1: excel_value | E1: python_value
A2: mean | B2: m4g_6b | C2: Items | D2: =AVERAGE(per_seed!$D$2:$D$11) -> 1419.9 | E2: 1419.9
A3: sd | B3: m4g_6b | C3: Items | D3: =_xlfn.STDEV.S(per_seed!$D$2:$D$11) -> 6.8223489 | E3: 6.8223489
A4: mean | B4: m4g_6b | C4: Lines | D4: =AVERAGE(per_seed!$E$2:$E$11) -> 946.1 | E4: 946.1
A5: sd | B5: m4g_6b | C5: Lines | D5: =_xlfn.STDEV.S(per_seed!$E$2:$E$11) -> 15.6237 | E5: 15.6237
A6: mean | B6: m4g_6b | C6: Orders | D6: =AVERAGE(per_seed!$F$2:$F$11) -> 599.1 | E6: 599.1
A7: sd | B7: m4g_6b | C7: Orders | D7: =_xlfn.STDEV.S(per_seed!$F$2:$F$11) -> 12.105554 | E7: 12.105554
A8: mean | B8: m4g_6b | C8: Pile-on | D8: =AVERAGE(per_seed!$G$2:$G$11) -> 5.3376678 | E8: 5.3376678
A9: sd | B9: m4g_6b | C9: Pile-on | D9: =_xlfn.STDEV.S(per_seed!$G$2:$G$11) -> 0.17628553 | E9: 0.17628553
A10: mean | B10: m4g_6b | C10: Trips | D10: =AVERAGE(per_seed!$H$2:$H$11) -> 112.3 | E10: 112.3
A11: sd | B11: m4g_6b | C11: Trips | D11: =_xlfn.STDEV.S(per_seed!$H$2:$H$11) -> 2.4966644 | E11: 2.4966644
A12: mean | B12: m4g_6b | C12: Trips/Orders | D12: =AVERAGE(per_seed!$I$2:$I$11) -> 0.18753467 | E12: 0.18753467
A13: sd | B13: m4g_6b | C13: Trips/Orders | D13: =_xlfn.STDEV.S(per_seed!$I$2:$I$11) -> 0.0062916126 | E13: 0.0062916126
A14: mean | B14: m4g_6b | C14: m/Line | D14: =AVERAGE(per_seed!$J$2:$J$11) -> 9.373574 | E14: 9.373574
A15: sd | B15: m4g_6b | C15: m/Line | D15: =_xlfn.STDEV.S(per_seed!$J$2:$J$11) -> 0.33887033 | E15: 0.33887033
A16: mean | B16: m4g_6b | C16: EOR(kJ/order) | D16: =AVERAGE(per_seed!$K$2:$K$11) -> 1.1895245 | E16: 1.1895245
A17: sd | B17: m4g_6b | C17: EOR(kJ/order) | D17: =_xlfn.STDEV.S(per_seed!$K$2:$K$11) -> 0.035017579 | E17: 0.035017579
A18: mean | B18: m4g_6b | C18: TurnoverMedian(s) | D18: =AVERAGE(per_seed!$L$2:$L$11) -> 830.78667 | E18: 830.78667
A19: sd | B19: m4g_6b | C19: TurnoverMedian(s) | D19: =_xlfn.STDEV.S(per_seed!$L$2:$L$11) -> 49.576436 | E19: 49.576436
A20: mean | B20: m4g_6b | C20: StationIdle(%) | D20: =AVERAGE(per_seed!$M$2:$M$11) -> 1.4530556 | E20: 1.4530556
A21: sd | B21: m4g_6b | C21: StationIdle(%) | D21: =_xlfn.STDEV.S(per_seed!$M$2:$M$11) -> 0.47133658 | E21: 0.47133658
A22: mean | B22: m4g_legacy_6b | C22: Items | D22: =AVERAGE(per_seed!$D$12:$D$21) -> 1407.8 | E22: 1407.8
A23: sd | B23: m4g_legacy_6b | C23: Items | D23: =_xlfn.STDEV.S(per_seed!$D$12:$D$21) -> 8.6384155 | E23: 8.6384155
A24: mean | B24: m4g_legacy_6b | C24: Lines | D24: =AVERAGE(per_seed!$E$12:$E$21) -> 939.5 | E24: 939.5
A25: sd | B25: m4g_legacy_6b | C25: Lines | D25: =_xlfn.STDEV.S(per_seed!$E$12:$E$21) -> 11.207636 | E25: 11.207636
A26: mean | B26: m4g_legacy_6b | C26: Orders | D26: =AVERAGE(per_seed!$F$12:$F$21) -> 589.7 | E26: 589.7
A27: sd | B27: m4g_legacy_6b | C27: Orders | D27: =_xlfn.STDEV.S(per_seed!$F$12:$F$21) -> 12.552556 | E27: 12.552556
A28: mean | B28: m4g_legacy_6b | C28: Pile-on | D28: =AVERAGE(per_seed!$G$12:$G$21) -> 4.414434 | E28: 4.414434
A29: sd | B29: m4g_legacy_6b | C29: Pile-on | D29: =_xlfn.STDEV.S(per_seed!$G$12:$G$21) -> 0.084468825 | E29: 0.084468825
A30: mean | B30: m4g_legacy_6b | C30: Trips | D30: =AVERAGE(per_seed!$H$12:$H$21) -> 133.6 | E30: 133.6
A31: sd | B31: m4g_legacy_6b | C31: Trips | D31: =_xlfn.STDEV.S(per_seed!$H$12:$H$21) -> 2.4585452 | E31: 2.4585452
A32: mean | B32: m4g_legacy_6b | C32: Trips/Orders | D32: =AVERAGE(per_seed!$I$12:$I$21) -> 0.22660497 | E32: 0.22660497
A33: sd | B33: m4g_legacy_6b | C33: Trips/Orders | D33: =_xlfn.STDEV.S(per_seed!$I$12:$I$21) -> 0.0043766917 | E33: 0.0043766917
A34: mean | B34: m4g_legacy_6b | C34: m/Line | D34: =AVERAGE(per_seed!$J$12:$J$21) -> 11.171753 | E34: 11.171753
A35: sd | B35: m4g_legacy_6b | C35: m/Line | D35: =_xlfn.STDEV.S(per_seed!$J$12:$J$21) -> 0.21214636 | E35: 0.21214636
A36: mean | B36: m4g_legacy_6b | C36: EOR(kJ/order) | D36: =AVERAGE(per_seed!$K$12:$K$21) -> 1.4291991 | E36: 1.4291991
A37: sd | B37: m4g_legacy_6b | C37: EOR(kJ/order) | D37: =_xlfn.STDEV.S(per_seed!$K$12:$K$21) -> 0.03339846 | E37: 0.03339846
A38: mean | B38: m4g_legacy_6b | C38: TurnoverMedian(s) | D38: =AVERAGE(per_seed!$L$12:$L$21) -> 858.85333 | E38: 858.85333
A39: sd | B39: m4g_legacy_6b | C39: TurnoverMedian(s) | D39: =_xlfn.STDEV.S(per_seed!$L$12:$L$21) -> 63.01907 | E39: 63.01907
A40: mean | B40: m4g_legacy_6b | C40: StationIdle(%) | D40: =AVERAGE(per_seed!$M$12:$M$21) -> 2.3157407 | E40: 2.3157407
...
